Traceback (most recent call last):
  File "/usr/local/lib/python2.7/dist-packages/datahaven/p2p/dhntester.py", line 16, in <module>
    import lib.dhnio as dhnio
ImportError: No module named lib.dhnio
Traceback (most recent call last):
  File "/usr/local/lib/python2.7/dist-packages/datahaven/p2p/dhntester.py", line 16, in <module>
    import lib.dhnio as dhnio
ImportError: No module named lib.dhnio
Traceback (most recent call last):
  File "/usr/local/lib/python2.7/dist-packages/datahaven/p2p/dhntester.py", line 16, in <module>
    import lib.dhnio as dhnio
ImportError: No module named lib.dhnio
Traceback (most recent call last):
  File "/usr/local/lib/python2.7/dist-packages/datahaven/p2p/dhntester.py", line 16, in <module>
    import lib.dhnio as dhnio
ImportError: No module named lib.dhnio
Traceback (most recent call last):
  File "/usr/local/lib/python2.7/dist-packages/datahaven/p2p/dhntester.py", line 16, in <module>
    import lib.dhnio as dhnio
ImportError: No module named lib.dhnio
Traceback (most recent call last):
  File "/usr/local/lib/python2.7/dist-packages/datahaven/p2p/dhntester.py", line 16, in <module>
    import lib.dhnio as dhnio
ImportError: No module named lib.dhnio
Traceback (most recent call last):
  File "/usr/local/lib/python2.7/dist-packages/datahaven/p2p/dhntester.py", line 16, in <module>
    import lib.dhnio as dhnio
ImportError: No module named lib.dhnio
Traceback (most recent call last):
  File "/usr/local/lib/python2.7/dist-packages/datahaven/p2p/dhntester.py", line 16, in <module>
    import lib.dhnio as dhnio
ImportError: No module named lib.dhnio
Traceback (most recent call last):
  File "/usr/local/lib/python2.7/dist-packages/datahaven/p2p/dhntester.py", line 16, in <module>
    import lib.dhnio as dhnio
ImportError: No module named lib.dhnio
Traceback (most recent call last):
  File "/usr/local/lib/python2.7/dist-packages/datahaven/p2p/dhntester.py", line 16, in <module>
    import lib.dhnio as dhnio
ImportError: No module named lib.dhnio
